Workbook

Sheet COSTI
A1: C | B1: RENDICONTAZIONE CONSUNTIVA
A3: C | B3: 1 | C3: COSTI
C5: A) Personale | D5: Costi preventivi (riportare i costi indicati nella richiesta di contributo) | E5: Totale costi consuntivi
D6: =+D145 -> 50000 | E6: =+E145 -> 50786.034
C8: Coordinamento (elencare il dettaglio dei documenti di spesa: numero, data di emissione, fornitore)
C10: Importo indicato in richiesta contributo | D10: 6468
C11: Ore di lavoro di Giulia Bariselli (vedi dettaglio in foglio "Personale dipendente G-LAB) | E11: =+'Personale dipendente G-LAB'!J3 -> 4980.1512
C12: Ore di lavoro di Claudia Cavassa (vedi dettaglio in foglio "Personale dipendente G-LAB) | E12: =+'Personale dipendente G-LAB'!J4 -> 4449.1776
C16: Consulenze/esperti (elencare il dettaglio dei documenti di spesa: numero, data di emissione, fornitore)
C17: Importo indicato in richiesta contributo | D17: 13112
C18: Attilio Ardito, formatore esperto. Notula del 31/03/2025 | E18: 367.44
C19: Ludovica Biondi, formatrice esperta. Fattura 5/25 del 28/03/2025 | E19: 310.7
C20: Esperti G-LAB per progettazione didattica: ore di lavoro di Jessica Maestrini (vedi dettaglio in foglio "Personale dipendente G-LAB) | E20: =+'Personale dipendente G-LAB'!J6 -> 4368.8352
C21: Esperti G-LAB per progettazione didattica: ore di lavoro di Paolo Manzi (vedi dettaglio in foglio "Personale dipendente G-LAB) | E21: =+'Personale dipendente G-LAB'!J5 -> 4614.1028
C22: Ludovica Biondi, formatrice esperta. Fattura 7/25 del 28/05/2025 | E22: 310.7
C23: Davide Colombi, formatore esperto. Fattura 9/A del 17/07/2025 | E23: 2822.4
C24: Davide Colombi, formatore esperto. Notula del 22/01/2025 | E24: 1500
C28: Formatori/operatori (elencare il dettaglio dei documenti di spesa: numero, data di emissione, fornitore)
C29: Importo indicato in richiesta contributo | D29: 18420
C30: Personale Cooperativa Progetto Crescita (vedi foglio di dettaglio) | E30: =+'Personale Coop. Crescita'!E14 -> 13843.51
C31: Formatori per attività didattica. Prima Tranches pagamento incarico. Fattura di Chrones SRL (P.IVA IT08822590728) FPR_EV 5/2024 del 05/11/2024 | E31: 2783.61
C32: Formatori per attività didattica. Seconda Tranches pagamento incarico. Fattura di Chrones SRL (P.IVA IT08822590728) FPR_EV 5/2025 del 26/05/2025 | E32: 5735.03
C33: Formatori per attività didattica. Fattura di Fondazione Parco Archeologico di Classe (P:IVA IT02042760393) | E33: 1613.36
C40: Assegnisti (elencare il dettaglio dei documenti di spesa: nome intestatario dell'assegno, numero, data di emissione)
C48: Borsisti (elencare il dettaglio dei documenti di spesa: nome dell'intestatario della borsa di studio, numero, data di emissione)
C56: Altro (specificare e delencare il dettaglio dei documenti di spesa: numero, data di emissione, fornitore)
C70: Sub. Totale A | D70: =SUM(D10:D69) -> 38000 | E70: =SUM(E10:E69) -> 47699.017
C73: B) Attrezzature
C74: Noleggio attrezzature (elencare il dettaglio dei documenti di spesa: numero, data di emissione, fornitore)
C86: Acquisto attrezzature (elencare il dettaglio dei documenti di spesa: numero, data di emissione, fornitore)
C88: Importo indicato in richiesta contributo | D88: 7000
C89: Fattura n. 36/gsi del 30/11/2024 GSI gruppo servizi informatici (voci evidenziate) | E89: 602
C98: Altro (specificare ed elencare il dettaglio dei documenti di spesa: numero, data di emissione, fornitore)
C112: Sub. Totale B | D112: =SUM(D75:D111) -> 7000 | E112: =SUM(E75:E111) -> 602
C115: C) Spese di produzione e divulgazione materiale di comunicazione
C116: (elencare il dettaglio dei documenti di spesa: numero, data di emissione, fornitore)
C126: Sub. Totale C | D126: =SUM(D117:D125) -> 0 | E126: =SUM(E117:E125) -> 0
C129: D) Altri costi connessi direttamente alla realizzazione del progetto
C130: (elencare il dettaglio dei documenti di spesa: numero, data di emissione, fornitore)
C131: Importo indicato in richiesta contributo spese generali | D131: 2000
...

Sheet Personale Coop. Crescita
A1: Dipendenete | B1: riferimento busta paga | C1: costo orario medio | D1: ore nel progetto | E1: costo progetto
A2: Battistini Mirco | B2: ott nr 50202 del 18/11/2024; nov 24 nr 50928 del 11/12/2024; dic nr 51972 del 21/01/2025; gen 25 nr 52698 del 13/02/2025; feb 25 nr. 53399 dl 11/03/2025; mar 25 bnr 54106 del 15/04/2025;apr 25 nr.54835 del 14/05/2025; mag 25 nr 5553 del 11/06/2025;giu 25 nr 56263 del 11/07/2025 | C2: 22.66 | D2: 64.5 | E2: =D2*C2 -> 1461.57
A3: Carzoli Dalila | B3: nov 24 nr 50999 del 11/12/2024; dic 24 nr 52045 del 21/01/2025 | C3: 21.47 | D3: 10 | E3: 214.7
A4: Gonzo Elvira | B4: nov 2 nr 51175 del 11/12/2024; dic 24 nr 52227 del 21/01/2025; gen 25 nbr 52947 del 3/02/2025; feb 25 nr. 53650 de 11/03/2025; mar 25 nr. 54360 del 15/04/2025; apr 2025 550825 del 14/05/2025; mag 25 nr 55801 del 11/06/2025 | C4: 20.48 | D4: 73.5 | E4: =+C4*D4 -> 1505.28
A5: Mandolesi Michela | B5: ott 24 nr 50517 del 18/11/2024; nov 24 nr. 51239 del 11/12/2024; dic 24 nr. 52295 del21/01/2025; gen 25 nr . 53013 del 13/02/2024; feb 24 nr. 53717 del 11/03/2025; mar 25 nr 54426 deel 15/04/2025 apr 25 nr 55156 del 14/05/2025; mag 25 nr 5867 del 11/06/2025 | C5: 20.83 | D5: 64.5 | E5: =+C5*D5 -> 1343.535
A6: Sturaro Martina | B6: mese sett. 24 nr .50040 del 21/10/2024 | C6: 21.51 | D6: 387 | E6: =+C6*D6 -> 8324.37
B7: ott. 24 nr. 50766 del 18/11/2024
B8: nov 24 nr. 51470 del 11/12/2024; dic 2 nr. 52538 del 21/01/2025; gen 25 nr 53241 del 13/02/2025; feb nr 53948 dl 11/03/2024;mar 25 nr 54663 del 15/04/2025; Aprv n 55392 del 14/05/2025; mag 25 nr 56101 del 11/05/2025; giu 25 nr 56896 del 11/07/2025
A9: Ravaioli Marta | B9: apr 25 nr 55314 del 14/05/2025; mag 25 nr 56022 del 11/06/2025 | C9: 20.71 | D9: 14.5 | E9: =+C9*D9 -> 300.295
A10: Spinella Serena | B10: apr 25 nr 55386 del 14/5/2025; mag 25 nr 56095 del 11/06/2025 | C10: 20.12 | D10: 17 | E10: =+C10*D10 -> 342.04
A11: Rambelli Stefano | B11: apr 25 nr 55304 del14/05/2025; mag 25 nr 5602 del 11/06/2025 | C11: 19.54 | D11: 18 | E11: =+C11*D11 -> 351.72
E14: =+SUM(E2:E11) -> 13843.51

Sheet Personale dipendente G-LAB
D1: 2024 | G1: 2025 | J1: TOT
A2: Dipendenti | B2: Voce budget | C2: Tipo di attività | D2: Costo orario* | E2: Ore | F2: Quantità | G2: Costo orario* | H2: Ore | I2: Quantità
A3: Giulia Bariselli, che ha lavorato al progetto 31 giorni lavorativi dal 10/07/2024 al 20/07/2025 | B3: Coordinamento | C3: Attività di management, rapporto con i partner, gestione amministrativa, compilazione di documenti progettuali e di rendicontazione | D3: 19.8 | E3: 128 | F3: =+E3*D3 -> 2534.4 | G3: 20.38126 | H3: =64+40+16 -> 120 | I3: =+H3*G3 -> 2445.7512 | J3: =+F3+I3 -> 4980.1512 | M3: =+(E3+H3)/8 -> 31
A4: Claudia Cavassa, che ha lavorato al progetto 32 giorni lavorativi dal 01/01/2025 al 20/07/2025 | B4: Coordinamento | C4: Attività di management, rapporto con le scuole e i formatori, calendarizzazione attività, segreteria didattica e rapporti con i pubblico | D4: 0 | E4: 0 | F4: =+E4*D4 -> 0 | G4: 17.3796 | H4: =120+80+40+16 -> 256 | I4: =+H4*G4 -> 4449.1776 | J4: =+F4+I4 -> 4449.1776 | M4: =+(E4+H4)/8 -> 32
A5: Paolo Manzi, che ha lavorato al progetto 26 giorni lavorativi dal 10/07/2024 al 20/07/2025 | B5: Consulenze/esperti | C5: Progettazione, rimodulazione, supporto ed erogazione di attività didattiche | D5: 22.25 | E5: 88 | F5: =+E5*D5 -> 1958 | G5: 22.13419 | H5: =136-88+40+16+16 -> 120 | I5: =+H5*G5 -> 2656.1028 | J5: =+F5+I5 -> 4614.1028 | M5: =+(E5+H5)/8 -> 26
A6: Jessica Maestrini, che ha lavorato al progetto 29 giorni lavorativi dal 10/07/2024 al 20/07/2025 | B6: Consulenze/esperti | C6: Progettazione, rimodulazione, supporto ed erogazione di attività didattiche | D6: 18.51 | E6: 104 | F6: =+E6*D6 -> 1925.04 | G6: 19.09215 | H6: =160-104+40+16+16 -> 128 | I6: =+H6*G6 -> 2443.7952 | J6: =+F6+I6 -> 4368.8352 | M6: =+(E6+H6)/8 -> 29
A8: TOT | D8: =+SUM(F3:F7) -> 6417.44 | G8: =+SUM(I3:I7) -> 11994.827 | J8: =+SUM(J3:J6) -> 18412.267
A10: *Per la quantificazione del costo orario si veda il documento "Ore certificate" allegato

Sheet Dettaglio materiale acquistato
A1: Nome fornitore | B1: Acquistato presso | C1: Detaglio acquisto | D1: Tipo documento | E1: Numero fattura | F1: Data Fattura | G1: Importo | H1: Importo con IVA a COSTO
A2: Grapefruit Tracie Kft | B2: AMAZON | C2: scatole portaoggetti | D2: fattura | E2: 407-1832778-0105140 | F2: 45573 | G2: 8.99 | H2: 10.17668
A3: Zhishi store | B3: AMAZON | C3: PD3504 40W 2C2A White IT3 | D3: fattura | E3: INV-IT- 407-2487941-3217926 | F3: 45573 | G3: 9.59 | H3: 10.85588
A4: FERLA FRANCESCO | B4: AMAZON | C4: 10 pz connettori alimentazione X2 (fattura da 15,10 € - IVA 20%) | D4: fattura elettronica | E4: 407-0217753-2723554 | F4: 45574 | G4: 12.58 | H4: 11.741333
A5: EMC HK Company Limited | B5: AMAZON | C5: cavo a spirale | D5: fattura | E5: 407-8519873-6645940 | F5: 45574 | G5: 15.7 | H5: 17.7724
A6: WuAi XinXi KeJi (Shanghai) YouXian GongSi | B6: AMAZON | C6: GreekPi 5Pack X2 | D6: fattura | E6: 407-0217753-2723554 | F6: 45574 | G6: 17.87 | H6: 20.22884
A7: Amazon EU S.a r.l., Succursale Italiana | B7: AMAZON | C7: chiavi USB | D7: fattura elettronica | E7: IT24-AEUl-12751278 | F7: 45576 | G7: 17.98 | H7: 16.684
A8: Shenzhen Zu Fang Bei Technology Company Limited | B8: AMAZON | C8: alimentatore 5V 10A X1 | D8: fattura | E8: 407-0217753-2723554 | F8: 45574 | G8: 18.01 | H8: 20.38732
A9: Shenzhenshi chengnuo keji youxian gongsi hangcheng jiedao huangtian shequ huangtian jinbi | B9: AMAZON | C9: micro 9g Servo Motore | D9: fattura | E9: 407-1832778-0105140 | F9: 45573 | G9: 18.02 | H9: 20.39864
A10: Shenzhen Hailege Technology Co Ud | B10: AMAZON | C10: Hellege 3pcs NANO X3 | D10: fattura | E10: 405-4 769817-5366702 | F10: 45590 | G10: 18.02 | H10: 20.39864
A11: AZ-Delivery Vertriebs GmbH | B11: AMAZON | C11: modulo PCA9685 X1 | D11: fattura | E11: 20244491849 | F11: 45573 | G11: 19.04 | H11: 21.55328
A12: changshahengfengdelipudianzishangwuyouxiangongsi xiangzhanglu255hao | B12: AMAZON | C12: cavo USB tipo C X3 | D12: fattura | E12: 407-8519873-6645940 | F12: 45574 | G12: 20.23 | H12: 22.90036
A13: Shenzhenshi guoyun dianzishangwu youxiangongsi | B13: AMAZON | C13: CAVETTI Jumper X4 | D13: fattura | E13: 407-8519873-6645940 | F13: 45574 | G13: 23.58 | H13: 26.69256
A14: Esselunga SPA | B14: ESSELUNGA | C14: spesa | D14: fattura elettronica | E14: 4241166401 | F14: 45588 | G14: 28.05 | H14: 26.206
A15: Shenzhen XinZhong Technology Co., Ltd. | B15: AMAZON | C15: 3M biadesivo X4 | D15: fattura | E15: 407-0217753-2723554 | F15: 45574 | G15: 29 | H15: 32.828
A16: g.L.L. GmbH Bauernvogtkoppel | B16: AMAZON | C16: mouse bluetooth | D16: fattura | E16: 407-2487941-3217926 | F16: 45593 | G16: 30.97 | H16: 35.05804
A17: shenzhenshiruoyekejiyouxiangongsi | B17: AMAZON | C17: servomotore | D17: fattura | E17: 407 -2487941-3217926 | F17: 45593 | G17: 33.74 | H17: 38.19368
A18: Commerciamo GmbH | B18: AMAZON | C18: Scatole 12,5 L x2 | D18: fattura | E18: 407-8519873-6645940 | F18: 45574 | G18: 42.02 | H18: 47.56664
A19: Shenzhen Enheji Keji Youxiangongsi Guanhu Jiedao | B19: AMAZON | C19: filamento | D19: fattura | E19: INV-ES-1193655535-2024-1956 € 42,16 | F19: 45574 | G19: 42.16 | H19: 47.72512
A20: Shangahai QiWai Technology Co., Ltd | B20: AMAZON | C20: set cacciaviti X5 | D20: fattura | E20: INV-IT-1490745005-2024-1859 | F20: 45574 | G20: 44.45 | H20: 50.3174
A21: ALWO SPOLKA Z OGRANICZONA ODPOWIEDZIALNOSCIA | B21: AMAZON | C21: compensato | D21: fattura | E21: INV-PL-162351181-2024-4870 | F21: 45574 | G21: 45.03 | H21: 50.97396
A22: Shenzhenshi guoyun dianzishangwu youxiangongsi | B22: AMAZON | C22: ELEGOO Kit Elettronico con Breadboard X4 | D22: fattura | E22: 407-2487941-3217926 | F22: 45593 | G22: 45.82 | H22: 51.86824
A23: HONG KONG UGREEN LIMITED | B23: AMAZON | C23: UGREEN Nexode | D23: fattura | E23: 407-0638727-1549158 | F23: 45573 | G23: 45.97 | H23: 52.03804
A24: Amazon EU S.a r.l., Succursale Italiana | B24: AMAZON | C24: multipresa 6 posti X5 | D24: fattura elettronica | E24: IT24-AEUl-12751278 | F24: 45576 | G24: 47.05 | H24: 43.65623
A25: AZ-Delivery Vertriebs GmbH | B25: AMAZON | C25: modulo PCA9685 X3 | D25: fattura | E25: 20244509946 | F25: 45573 | G25: 57.15 | H25: 64.6938
A26: SHENZHENANQITESHANGMAOYOUXIANGONGSIXINCUIYAYUAN 1 DONG C DANYUAN 701SHI | B26: AMAZON | C26: alimentatori X5 | D26: fattura | E26: INV-IT-508151275-2024-1736 | F26: 45573 | G26: 59.4 | H26: 67.2408
A27: Shenzhen Zu Fang Bei Technology Company Limiled | B27: AMAZON | C27: alimentatore 5V 10A X5 | D27: fattura | E27: 407-0217753-2723554 | F27: 45574 | G27: 90.05 | H27: 101.9366
A28: nmak KERBAL LTD CO.LTD | B28: AMAZON | C28: Queta Micro Servomotore | D28: fattura | E28: 49083748 | F28: 45573 | G28: 94.95 | H28: 107.4834
A29: Arduino S.r.l. | B29: AMAZON | C29: Arduino nano X5 | D29: fattura elettronica | E29: IT24-59865I-2803 | F29: 45590 | G29: 112.4 | H29: 104.29246
A30: Arduino S.r.l. | B30: AMAZON | C30: Arduino UNO R4 X5 | D30: fattura elettronica | E30: IT24-59865I-2579 | F30: 45573 | G30: 147.95 | H30: 137.2782
A31: Shen zhen shi jiu man ke ji you xian gong si | B31: AMAZON | C31: EGSTARTS 2 Giocatori USB Controller per PC Game 2X 5Pin Stick + 4X 24mm + 16x 30mm Pulsanti per Giochi Arcade Kit armadietti Fai da Te Parti Mame SNK | D31: fattura | E31: IT50002MWP1YHI | F31: 45762 | G31: 30.32 | H31: 35.122688
A32: Amazon EU S.a r.l., Succursale Italiana | B32: AMAZON | C32: AREXONS | Smalto 100% Acrilico Smalto sprayRosso + lucido | D32: fattura elettronica | E32: IT25-AEUI-6020322 | F32: 45786 | G32: 11.05 | H32: 10.4928
A33: JENOLITE (UK) LTD | B33: AMAZON | C33: primer per plastiche | D33: fattura | E33: IT5000K59ND69I | F33: 45786 | G33: 13.23 | H33: 15.325632
A34: Ar-store di Raspugli Andrea | B34: AMAZON | C34: varie | D34: fattura elettronica | E34: IT50028PIAM3VI | F34: 45789 | G34: 17.54 | H34: 16.6552
A35: Amazon EU S.a r.l., Succursale Italiana | B35: AMAZON | C35: AREXONS | Smalto 100% Acrilico Smalto spray Nero+ Bianco | D35: fattura elettronica | E35: IT25-AEUI-6034836 | F35: 45787 | G35: 22.1 | H35: 20.98
A36: DM SOLUZIONI ICT srl | B36: AMAZON | C36: Rii Gaming GP100 - Coppia Gamepad Controller USB compatibili con PC (Windows, Mac, Linux) e Raspberry Pi | D36: fattura elettronica | E36: IT5000PU54I8JI | F36: 45795 | G36: 24.95 | H36: 23.6928
A37: DM SOLUZIONI ICT srl | B37: AMAZON | C37: Rii Gaming GP100 - Coppia Gamepad Controller USB compatibili con PC (Windows, Mac, Linux) e Raspberry Pi | D37: fattura elettronica | E37: IT5000QA54I8JI | F37: 45797 | G37: 24.95 | H37: 23.6928
A38: SIA TROD AR | B38: AMAZON | C38: Cavo HDMI a VGA da 1,8 m (fattura da 37,45€ ma ricevuta da 35,58€) | D38: fattura | E38: 408-3104167-3181169 | F38: 45785 | G38: 37.45 | H38: 43.38208
A39: guangzhouhuayueguojimaoyiyouxianzerengongsi | B39: AMAZON | C39: HUAZIZ 8 Pezzi 9G Micro Servo Motore per Braccio Robot RC/Mano/Elicottero Barca Aeroplano Auto Veicoli Modelli di Controllo, Servos Mini Micro Motore per Arduino | D39: fattura | E39: IT5001JR1JTE7I | F39: 45785 | G39: 38.91 | H39: 45.073344
A40: Amazon EU S.a r.l., Succursale Italiana | B40: AMAZON | C40: DIGITUS supporto a parete per monitor LCD/LED fino a 81 cm (32"), staffa di fissaggio, carico massimo 18 kg, VESA 75x75 e 100x100 | D40: fattura elettronica | E40: IT25-AEUI-5960696 | F40: 45785 | G40: 44.95 | H40: 42.6848
...
